Workbook

Sheet Dashboard
A1: 🎬 CONOR'S BLU-RAY COLLECTION
A2: Physical media tracker • collection progress • wishlist • franchise completion
A4: COLLECTION | B4: VALUE | D4: FOUNDATION | E4: VALUE | G4: WISHLIST | H4: VALUE
A5: Individual films | B5: =COUNTIF(Collection!B5:B500,"<>") | D5: Film IDs | E5: =COUNTA(Collection!A5:A500) | G5: Total wishlist | H5: =COUNTA(Wishlist!A5:A100)
A6: Blu-ray entries | B6: =COUNTIF(Collection!D5:D500,"Blu-ray") | D6: Years filled | E6: =COUNTA(Collection!C5:C500) | G6: Your requested films | H6: =COUNTIF(Wishlist!B5:B100,"Your list")
A7: 4K UHD entries | B7: =COUNTIF(Collection!D5:D500,"4K UHD") | D7: Directors filled | E7: =COUNTIF(Collection!J5:J500,"<>") | G7: Recommendations | H7: =COUNTIF(Wishlist!B5:B100,"Recommended")
A8: Watched | B8: =COUNTIF(Collection!G5:G500,"Yes") | D8: Box-set films | E8: =COUNTIF(Collection!F5:F500,"Back to the Future Trilogy (Box Set)")+COUNTIF(Collection!F5:F500,"Bad Boys I & II (Box Set)")+COUNTIF(Collection!F5:F500,"Cornetto Trilogy (Box Set)")+COUNTIF(Collection!F5:F500,"Jurassic Park / World: 7-Film Collection")+COUNTIF(Collection!F5:F500,"The Lord of the Rings Trilogy (Box Set)")+COUNTIF(Collection!F5:F500,"Star Wars Episodes I–VI (Box Set)")+COUNTIF(Collection!F5:F500,"X-Men Trilogy (Box Set)") | G8: Already owned | H8: =COUNTIF(Wishlist!H5:H100,"Yes")
A9: Rated | B9: =COUNT(Collection!H5:H500) | D9: Collections tracked | E9: =COUNTA('Franchise Tracker'!A5:A47) | G9: Still to buy | H9: =COUNTIF(Wishlist!H5:H100,"No")
A12: COLLECTION | B12: OWNED | C12: TARGET | D12: MISSING | E12: COMPLETE | G12: AWARDS | H12: VALUE
A13: ='Franchise Tracker'!A5 | B13: ='Franchise Tracker'!B5 | C13: ='Franchise Tracker'!C5 | D13: ='Franchise Tracker'!D5 | E13: ='Franchise Tracker'!E5 | G13: Oscar-nominated films | H13: =COUNTIF(Collection!U5:U500,">0")
A14: ='Franchise Tracker'!A6 | C14: ='Franchise Tracker'!C6 | D14: ='Franchise Tracker'!D6 | E14: ='Franchise Tracker'!E6 | G14: Oscar-winning films | H14: =COUNTIF(Collection!V5:V500,">0")
A15: ='Franchise Tracker'!A7 | B15: ='Franchise Tracker'!B7 | C15: ='Franchise Tracker'!C7 | D15: ='Franchise Tracker'!D7 | E15: ='Franchise Tracker'!E7 | G15: Total nominations | H15: =SUM(Collection!U5:U500)
A16: ='Franchise Tracker'!A8 | B16: ='Franchise Tracker'!B8 | C16: ='Franchise Tracker'!C8 | D16: ='Franchise Tracker'!D8 | E16: ='Franchise Tracker'!E8 | G16: Total wins | H16: =SUM(Collection!V5:V500)
A17: ='Franchise Tracker'!A9 | B17: ='Franchise Tracker'!B9 | C17: ='Franchise Tracker'!C9 | D17: ='Franchise Tracker'!D9 | E17: ='Franchise Tracker'!E9 | G17: Best Picture winners | H17: =COUNTIF(Collection!W5:W500,"Winner")
A18: ='Franchise Tracker'!A10 | B18: ='Franchise Tracker'!B10 | C18: ='Franchise Tracker'!C10 | D18: ='Franchise Tracker'!D10 | E18: ='Franchise Tracker'!E10 | G18: Best Picture nominees | H18: =COUNTIF(Collection!W5:W500,"Winner")+COUNTIF(Collection!W5:W500,"Nominated")
A19: ='Franchise Tracker'!A11 | B19: ='Franchise Tracker'!B11 | C19: ='Franchise Tracker'!C11 | D19: ='Franchise Tracker'!D11 | E19: ='Franchise Tracker'!E11 | G19: Best Picture progress | H19: =H17/98
A20: ='Franchise Tracker'!A12 | B20: ='Franchise Tracker'!B12 | C20: ='Franchise Tracker'!C12 | D20: ='Franchise Tracker'!D12 | E20: ='Franchise Tracker'!E12 | G20: Animated Feature winners | H20: =COUNTIF(Awards!O5:O500,"Winner")
A21: ='Franchise Tracker'!A13 | B21: ='Franchise Tracker'!B13 | C21: ='Franchise Tracker'!C13 | D21: ='Franchise Tracker'!D13 | E21: ='Franchise Tracker'!E13 | G21: Acting-winning films | H21: =COUNTIF(Awards!H5:H500,">0")
A22: ='Franchise Tracker'!A14 | B22: ='Franchise Tracker'!B14 | C22: ='Franchise Tracker'!C14 | D22: ='Franchise Tracker'!D14 | E22: ='Franchise Tracker'!E14 | G22: Directing-winning films | H22: =COUNTIF(Awards!K5:K500,">0")
A25: ⭐ RATINGS OVERVIEW
A27: RATINGS | B27: VALUE | D27: SOURCE COVERAGE | E27: FILMS
A28: Your films rated | B28: =COUNT(Ratings!D5:D500) | D28: IMDb | E28: =COUNT(Ratings!E5:E500)
A29: External ratings entered | B29: =COUNT(Ratings!L5:L500) | D29: Rotten Tomatoes critics | E29: =COUNT(Ratings!G5:G500)
A30: Average consensus | B30: =IFERROR(AVERAGE(Ratings!L5:L500),0) | D30: Rotten Tomatoes audience | E30: =COUNT(Ratings!H5:H500)
A31: Excellent (85+) | B31: =COUNTIF(Ratings!M5:M500,"Excellent") | D31: Letterboxd | E31: =COUNT(Ratings!I5:I500)
A32: Good (70–84.9) | B32: =COUNTIF(Ratings!M5:M500,"Good") | D32: Metacritic | E32: =COUNT(Ratings!J5:J500)
A33: Mixed (55–69.9) | B33: =COUNTIF(Ratings!M5:M500,"Mixed") | D33: TMDb | E33: =COUNT(Ratings!K5:K500)
A34: Poor (<55) | B34: =COUNTIF(Ratings!M5:M500,"Poor") | D34: Consensus | E34: =COUNT(Ratings!L5:L500)

Sheet Collection
A1: 🎬 MY BLU-RAY COLLECTION — v5.0
A2: Ratings edition: dedicated ratings database added with your score, external-rating fields, consensus scoring and one-click source lookups.
A4: Film ID | B4: Title | C4: Year | D4: Format | E4: Collection | F4: Physical Release / Box Set | G4: Watched | H4: Rating (1-5) | I4: Notes | J4: Director | K4: Runtime (min) | L4: Genre | M4: Studio / Production | N4: Metadata Source | O4: Cast Source | P4: Actor 1 | Q4: Actor 2 | R4: Actor 3 | S4: Actor 4 | T4: Actor 5 | U4: Oscar Noms | V4: Oscar Wins | W4: Best Picture | X4: IMDb | Y4: RT Critics | Z4: Letterboxd | AA4: Date Watched
A5: F0001 | B5: Casino Royale | C5: 2006 | D5: Blu-ray | E5: James Bond | I5: Le Chiffre, a banker to the world's terrorists, is scheduled to participate in a high-stakes poker game in Montenegro, where he intends to use his winnings to establish his financial grip on the terrorist market. M sends Bond—on his maiden mission as a 00 Agent—to attend this game and prevent Le Chiffre from winning. With the help of Vesper Lynd and Felix Leiter, Bond enters the most important poker game in his already dangerous career. | J5: Martin Campbell | K5: 144 | L5: Adventure, Action, Thriller | M5: Eon Productions, Stillking Films, Columbia Pictures | N5: https://huggingface.co/datasets/HenryWaltson/TMDB-IMDB-Movies-Dataset | O5: https://huggingface.co/datasets/HenryWaltson/TMDB-IMDB-Movies-Dataset | P5: Daniel Craig | Q5: Eva Green | R5: Mads Mikkelsen | S5: Judi Dench | T5: Jeffrey Wright | U5: 0 | V5: 0 | X5: =IFERROR(INDEX(Ratings!$E$5:$E$500,MATCH(A5,Ratings!$A$5:$A$500,0)),"") | Y5: =IFERROR(INDEX(Ratings!$G$5:$G$500,MATCH(A5,Ratings!$A$5:$A$500,0)),"") | Z5: =IFERROR(INDEX(Ratings!$I$5:$I$500,MATCH(A5,Ratings!$A$5:$A$500,0)),"")
A6: F0002 | B6: Quantum of Solace | C6: 2008 | D6: Blu-ray | E6: James Bond | I6: Betrayed by Vesper, the woman he loved, 007 fights the urge to make his latest mission personal. Pursuing his determination to uncover the truth, Bond and M interrogate Mr. White, who reveals that the organization that blackmailed Vesper is far more complex and dangerous than anyone had imagined. | J6: Marc Forster | K6: 106 | L6: Adventure, Action, Thriller, Crime | M6: Eon Productions, Metro-Goldwyn-Mayer, Columbia Pictures | N6: https://huggingface.co/datasets/HenryWaltson/TMDB-IMDB-Movies-Dataset | O6: https://huggingface.co/datasets/HenryWaltson/TMDB-IMDB-Movies-Dataset | P6: Daniel Craig | Q6: Olga Kurylenko | R6: Mathieu Amalric | S6: Judi Dench | T6: Giancarlo Giannini | U6: 0 | V6: 0 | X6: =IFERROR(INDEX(Ratings!$E$5:$E$500,MATCH(A6,Ratings!$A$5:$A$500,0)),"") | Y6: =IFERROR(INDEX(Ratings!$G$5:$G$500,MATCH(A6,Ratings!$A$5:$A$500,0)),"") | Z6: =IFERROR(INDEX(Ratings!$I$5:$I$500,MATCH(A6,Ratings!$A$5:$A$500,0)),"")
A7: F0003 | B7: Skyfall | C7: 2012 | D7: Blu-ray | E7: James Bond | I7: When Bond's latest assignment goes gravely wrong, agents around the world are exposed and MI6 headquarters is attacked. While M faces challenges to her authority and position from Gareth Mallory, the new Chairman of the Intelligence and Security Committee, it's up to Bond, aided only by field agent Eve, to locate the mastermind behind the attack. | J7: Sam Mendes | K7: 143 | L7: Action, Adventure, Thriller | M7: Metro-Goldwyn-Mayer, Eon Productions, Danjaq | N7: https://huggingface.co/datasets/HenryWaltson/TMDB-IMDB-Movies-Dataset | O7: https://huggingface.co/datasets/HenryWaltson/TMDB-IMDB-Movies-Dataset | P7: Daniel Craig | Q7: Judi Dench | R7: Javier Bardem | S7: Ralph Fiennes | T7: Naomie Harris | U7: 5 | V7: 2 | X7: =IFERROR(INDEX(Ratings!$E$5:$E$500,MATCH(A7,Ratings!$A$5:$A$500,0)),"") | Y7: =IFERROR(INDEX(Ratings!$G$5:$G$500,MATCH(A7,Ratings!$A$5:$A$500,0)),"") | Z7: =IFERROR(INDEX(Ratings!$I$5:$I$500,MATCH(A7,Ratings!$A$5:$A$500,0)),"")
A8: F0004 | B8: Spectre | C8: 2015 | D8: Blu-ray | E8: James Bond | I8: A cryptic message from Bond’s past sends him on a trail to uncover a sinister organization. While M battles political forces to keep the secret service alive, Bond peels back the layers of deceit to reveal the terrible truth behind SPECTRE. | J8: Sam Mendes | K8: 148 | L8: Action, Adventure, Thriller | M8: Columbia Pictures, Metro-Goldwyn-Mayer, Eon Productions | N8: https://huggingface.co/datasets/HenryWaltson/TMDB-IMDB-Movies-Dataset | O8: https://huggingface.co/datasets/HenryWaltson/TMDB-IMDB-Movies-Dataset | P8: Daniel Craig | Q8: Christoph Waltz | R8: Léa Seydoux | S8: Ralph Fiennes | T8: Monica Bellucci | U8: 1 | V8: 1 | X8: =IFERROR(INDEX(Ratings!$E$5:$E$500,MATCH(A8,Ratings!$A$5:$A$500,0)),"") | Y8: =IFERROR(INDEX(Ratings!$G$5:$G$500,MATCH(A8,Ratings!$A$5:$A$500,0)),"") | Z8: =IFERROR(INDEX(Ratings!$I$5:$I$500,MATCH(A8,Ratings!$A$5:$A$500,0)),"")
A9: F0005 | B9: No Time to Die | C9: 2021 | D9: Blu-ray | E9: James Bond | I9: Bond has left active service and is enjoying a tranquil life in Jamaica. His peace is short-lived when his old friend Felix Leiter from the CIA turns up asking for help. The mission to rescue a kidnapped scientist turns out to be far more treacherous than expected, leading Bond onto the trail of a mysterious villain armed with dangerous new technology. | J9: Cary Joji Fukunaga | K9: 163 | L9: Action, Thriller, Romance | M9: Eon Productions, Metro-Goldwyn-Mayer, Universal Pictures | N9: https://huggingface.co/datasets/HenryWaltson/TMDB-IMDB-Movies-Dataset | O9: https://huggingface.co/datasets/HenryWaltson/TMDB-IMDB-Movies-Dataset | P9: Daniel Craig | Q9: Léa Seydoux | R9: Rami Malek | S9: Lashana Lynch | T9: Ralph Fiennes | U9: 3 | V9: 1 | X9: =IFERROR(INDEX(Ratings!$E$5:$E$500,MATCH(A9,Ratings!$A$5:$A$500,0)),"") | Y9: =IFERROR(INDEX(Ratings!$G$5:$G$500,MATCH(A9,Ratings!$A$5:$A$500,0)),"") | Z9: =IFERROR(INDEX(Ratings!$I$5:$I$500,MATCH(A9,Ratings!$A$5:$A$500,0)),"")
A10: F0006 | B10: 2012 | C10: 2009 | D10: Blu-ray | I10: Dr. Adrian Helmsley, part of a worldwide geophysical team investigating the effect on the earth of radiation from unprecedented solar storms, learns that the earth's core is heating up. He warns U.S. President Thomas Wilson that the crust of the earth is becoming unstable and that without proper preparations for saving a fraction of the world's population, the entire race is doomed. Meanwhile, writer Jackson Curtis stumbles on the same information. While the world's leaders race to build "arks" to escape the impending cataclysm, Curtis struggles to find a way to save his family. Meanwhile, volcanic eruptions and earthquakes of unprecedented strength wreak havoc around the world. | J10: Roland Emmerich | K10: 158 | L10: Action, Adventure, Science Fiction | M10: Columbia Pictures, Centropolis Entertainment, Farewell Productions | N10: https://huggingface.co/datasets/HenryWaltson/TMDB-IMDB-Movies-Dataset | O10: https://huggingface.co/datasets/HenryWaltson/TMDB-IMDB-Movies-Dataset | P10: John Cusack | Q10: Amanda Peet | R10: Chiwetel Ejiofor | S10: Thandiwe Newton | T10: Oliver Platt | U10: 0 | V10: 0 | X10: =IFERROR(INDEX(Ratings!$E$5:$E$500,MATCH(A10,Ratings!$A$5:$A$500,0)),"") | Y10: =IFERROR(INDEX(Ratings!$G$5:$G$500,MATCH(A10,Ratings!$A$5:$A$500,0)),"") | Z10: =IFERROR(INDEX(Ratings!$I$5:$I$500,MATCH(A10,Ratings!$A$5:$A$500,0)),"")
A11: F0007 | B11: 21 Jump Street | C11: 2012 | D11: Blu-ray | E11: Jump Street | G11: Yes | H11: ⭐⭐⭐⭐ | I11: When cops Schmidt and Jenko join the secret Jump Street unit, they use their youthful appearances to go undercover as high school students. They trade in their guns and badges for backpacks, and set out to shut down a dangerous drug ring. But, as time goes on, Schmidt and Jenko discover that high school is nothing like it was just a few years earlier -- and, what's more, they must again confront the teenage terror and anxiety they thought they had left behind. | J11: Phil Lord, Christopher Miller | K11: 109 | L11: Action, Comedy, Crime | M11: Columbia Pictures, Relativity Media, Original Film | N11: https://huggingface.co/datasets/HenryWaltson/TMDB-IMDB-Movies-Dataset | O11: https://huggingface.co/datasets/HenryWaltson/TMDB-IMDB-Movies-Dataset | P11: Jonah Hill | Q11: Channing Tatum | R11: Brie Larson | S11: Dave Franco | T11: Rob Riggle | U11: 0 | V11: 0 | X11: =IFERROR(INDEX(Ratings!$E$5:$E$500,MATCH(A11,Ratings!$A$5:$A$500,0)),"") | Y11: =IFERROR(INDEX(Ratings!$G$5:$G$500,MATCH(A11,Ratings!$A$5:$A$500,0)),"") | Z11: =IFERROR(INDEX(Ratings!$I$5:$I$500,MATCH(A11,Ratings!$A$5:$A$500,0)),"")
A12: F0008 | B12: 22 Jump Street | C12: 2014 | D12: Blu-ray | E12: Jump Street | I12: After making their way through high school (twice), big changes are in store for officers Schmidt and Jenko when they go deep undercover at a local college. But when Jenko meets a kindred spirit on the football team, and Schmidt infiltrates the bohemian art major scene, they begin to question their partnership. Now they don't have to just crack the case - they have to figure out if they can have a mature relationship. If these two overgrown adolescents can grow from freshmen into real men, college might be the best thing that ever happened to them. | J12: Phil Lord, Christopher Miller | K12: 112 | L12: Crime, Comedy, Action | M12: Columbia Pictures, Original Film, MRC | N12: https://huggingface.co/datasets/HenryWaltson/TMDB-IMDB-Movies-Dataset | O12: https://huggingface.co/datasets/HenryWaltson/TMDB-IMDB-Movies-Dataset | P12: Jonah Hill | Q12: Channing Tatum | R12: Peter Stormare | S12: Wyatt Russell | T12: Amber Stevens West | U12: 0 | V12: 0 | X12: =IFERROR(INDEX(Ratings!$E$5:$E$500,MATCH(A12,Ratings!$A$5:$A$500,0)),"") | Y12: =IFERROR(INDEX(Ratings!$G$5:$G$500,MATCH(A12,Ratings!$A$5:$A$500,0)),"") | Z12: =IFERROR(INDEX(Ratings!$I$5:$I$500,MATCH(A12,Ratings!$A$5:$A$500,0)),"")
A13: F0009 | B13: 30 Minutes or Less | C13: 2011 | D13: Blu-ray | I13: Two fledgling criminals kidnap a pizza delivery guy, strap a bomb to his chest, and advise him that he has mere hours to rob a bank or else... | J13: Ruben Fleischer | K13: 83 | L13: Action, Adventure, Comedy | M13: Columbia Pictures | N13: https://huggingface.co/datasets/HenryWaltson/TMDB-IMDB-Movies-Dataset | O13: https://huggingface.co/datasets/HenryWaltson/TMDB-IMDB-Movies-Dataset | P13: Jesse Eisenberg | Q13: Aziz Ansari | R13: Danny McBride | S13: Nick Swardson | T13: Dilshad Vadsaria | U13: 0 | V13: 0 | X13: =IFERROR(INDEX(Ratings!$E$5:$E$500,MATCH(A13,Ratings!$A$5:$A$500,0)),"") | Y13: =IFERROR(INDEX(Ratings!$G$5:$G$500,MATCH(A13,Ratings!$A$5:$A$500,0)),"") | Z13: =IFERROR(INDEX(Ratings!$I$5:$I$500,MATCH(A13,Ratings!$A$5:$A$500,0)),"")
A14: F0010 | B14: 44 Inch Chest | C14: 2009 | D14: Blu-ray | I14: Colin is in agony, shattered by his wife’s infidelity, so his friends kidnap the wife's lover so he can have his revenge. | J14: Malcolm Venville | K14: 95 | L14: Drama, Crime | M14: Omni Films, Prescience Media, Twilight Production & Entertainment | N14: https://huggingface.co/datasets/HenryWaltson/TMDB-IMDB-Movies-Dataset | O14: https://huggingface.co/datasets/HenryWaltson/TMDB-IMDB-Movies-Dataset | P14: Ray Winstone | Q14: John Hurt | R14: Ian McShane | S14: Tom Wilkinson | T14: Joanne Whalley | U14: 0 | V14: 0 | X14: =IFERROR(INDEX(Ratings!$E$5:$E$500,MATCH(A14,Ratings!$A$5:$A$500,0)),"") | Y14: =IFERROR(INDEX(Ratings!$G$5:$G$500,MATCH(A14,Ratings!$A$5:$A$500,0)),"") | Z14: =IFERROR(INDEX(Ratings!$I$5:$I$500,MATCH(A14,Ratings!$A$5:$A$500,0)),"")
A15: F0011 | B15: 50/50 | C15: 2011 | D15: Blu-ray | I15: Inspired by a true story, a comedy centered on a 27-year-old guy who learns of his cancer diagnosis and his subsequent struggle to beat the disease. | J15: Jonathan Levine | K15: 100 | L15: Comedy, Drama | M15: Summit Entertainment, Mandate Pictures, Point Grey Pictures | N15: https://huggingface.co/datasets/HenryWaltson/TMDB-IMDB-Movies-Dataset | O15: https://huggingface.co/datasets/HenryWaltson/TMDB-IMDB-Movies-Dataset | P15: Joseph Gordon-Levitt | Q15: Seth Rogen | R15: Anna Kendrick | S15: Bryce Dallas Howard | T15: Philip Baker Hall | U15: 0 | V15: 0 | X15: =IFERROR(INDEX(Ratings!$E$5:$E$500,MATCH(A15,Ratings!$A$5:$A$500,0)),"") | Y15: =IFERROR(INDEX(Ratings!$G$5:$G$500,MATCH(A15,Ratings!$A$5:$A$500,0)),"") | Z15: =IFERROR(INDEX(Ratings!$I$5:$I$500,MATCH(A15,Ratings!$A$5:$A$500,0)),"")
A16: F0012 | B16: A Bug's Life | C16: 1998 | D16: Blu-ray | G16: Yes | H16: ⭐⭐⭐⭐ | I16: On behalf of "oppressed bugs everywhere," an inventive ant named Flik hires a troupe of warrior bugs to defend his bustling colony from a horde of freeloading grasshoppers led by the evil-minded Hopper. | J16: John Lasseter, Andrew Stanton | K16: 95 | L16: Adventure, Animation, Comedy, Family | M16: Pixar, Walt Disney Pictures | N16: https://huggingface.co/datasets/HenryWaltson/TMDB-IMDB-Movies-Dataset | O16: https://huggingface.co/datasets/HenryWaltson/TMDB-IMDB-Movies-Dataset | P16: Dave Foley | Q16: Kevin Spacey | R16: Julia Louis-Dreyfus | S16: Hayden Panettiere | T16: Phyllis Diller | U16: 1 | V16: 0 | X16: =IFERROR(INDEX(Ratings!$E$5:$E$500,MATCH(A16,Ratings!$A$5:$A$500,0)),"") | Y16: =IFERROR(INDEX(Ratings!$G$5:$G$500,MATCH(A16,Ratings!$A$5:$A$500,0)),"") | Z16: =IFERROR(INDEX(Ratings!$I$5:$I$500,MATCH(A16,Ratings!$A$5:$A$500,0)),"")
A17: F0013 | B17: The Accountant | C17: 2016 | D17: Blu-ray | I17: As a math savant uncooks the books for a new client, the Treasury Department closes in on his activities and the body count starts to rise. | J17: Gavin O'Connor | K17: 128 | L17: Crime, Thriller, Drama | M17: Zero Gravity Management, Electric City Entertainment, RatPac Entertainment | N17: https://huggingface.co/datasets/HenryWaltson/TMDB-IMDB-Movies-Dataset | O17: https://huggingface.co/datasets/HenryWaltson/TMDB-IMDB-Movies-Dataset | P17: Ben Affleck | Q17: Cynthia Addai-Robinson | R17: Anna Kendrick | S17: J.K. Simmons | T17: Jon Bernthal | U17: 0 | V17: 0 | X17: =IFERROR(INDEX(Ratings!$E$5:$E$500,MATCH(A17,Ratings!$A$5:$A$500,0)),"") | Y17: =IFERROR(INDEX(Ratings!$G$5:$G$500,MATCH(A17,Ratings!$A$5:$A$500,0)),"") | Z17: =IFERROR(INDEX(Ratings!$I$5:$I$500,MATCH(A17,Ratings!$A$5:$A$500,0)),"")
A18: F0014 | B18: Alan Partridge: Alpha Papa | C18: 2013 | D18: Blu-ray | I18: When famous DJ Alan Partridge’s radio station is taken over by a new media conglomerate, it sets in motion a chain of events which see Alan having to work with the police to defuse a potentially violent siege. | J18: Declan Lowney | K18: 90 | L18: Comedy | M18: BFI, BBC Film, StudioCanal | N18: https://huggingface.co/datasets/HenryWaltson/TMDB-IMDB-Movies-Dataset | O18: https://huggingface.co/datasets/HenryWaltson/TMDB-IMDB-Movies-Dataset | P18: Steve Coogan | Q18: Colm Meaney | R18: Felicity Montagu | S18: Simon Greenall | T18: Anna Maxwell Martin | U18: 0 | V18: 0 | X18: =IFERROR(INDEX(Ratings!$E$5:$E$500,MATCH(A18,Ratings!$A$5:$A$500,0)),"") | Y18: =IFERROR(INDEX(Ratings!$G$5:$G$500,MATCH(A18,Ratings!$A$5:$A$500,0)),"") | Z18: =IFERROR(INDEX(Ratings!$I$5:$I$500,MATCH(A18,Ratings!$A$5:$A$500,0)),"")
A19: F0015 | B19: Alien | C19: 1979 | D19: Blu-ray | E19: Alien | I19: During its return to the earth, commercial spaceship Nostromo intercepts a distress signal from a distant planet. When a three-member team of the crew discovers a chamber containing thousands of eggs on the planet, a creature inside one of the eggs attacks an explorer. The entire crew is unaware of the impending nightmare set to descend upon them when the alien parasite planted inside its unfortunate host is birthed. | J19: Ridley Scott | K19: 117 | L19: Horror, Science Fiction | M19: Brandywine Productions, 20th Century Fox | N19: https://huggingface.co/datasets/HenryWaltson/TMDB-IMDB-Movies-Dataset | O19: https://huggingface.co/datasets/HenryWaltson/TMDB-IMDB-Movies-Dataset | P19: Tom Skerritt | Q19: Sigourney Weaver | R19: Veronica Cartwright | S19: Harry Dean Stanton | T19: John Hurt | U19: 2 | V19: 1 | X19: =IFERROR(INDEX(Ratings!$E$5:$E$500,MATCH(A19,Ratings!$A$5:$A$500,0)),"") | Y19: =IFERROR(INDEX(Ratings!$G$5:$G$500,MATCH(A19,Ratings!$A$5:$A$500,0)),"") | Z19: =IFERROR(INDEX(Ratings!$I$5:$I$500,MATCH(A19,Ratings!$A$5:$A$500,0)),"")
A20: F0016 | B20: Aliens | C20: 1986 | D20: Blu-ray | E20: Alien | I20: Ripley, the sole survivor of the Nostromo's deadly encounter with the monstrous Alien, returns to Earth after drifting through space in hypersleep for 57 years. Although her story is initially met with skepticism, she agrees to accompany a team of Colonial Marines back to LV-426. | J20: James Cameron | K20: 137 | L20: Action, Thriller, Science Fiction | M20: Brandywine Productions, SLM Production Group, 20th Century Fox | N20: https://huggingface.co/datasets/HenryWaltson/TMDB-IMDB-Movies-Dataset | O20: https://huggingface.co/datasets/HenryWaltson/TMDB-IMDB-Movies-Dataset | P20: Sigourney Weaver | Q20: Carrie Henn | R20: Michael Biehn | S20: Paul Reiser | T20: Lance Henriksen | U20: 7 | V20: 2 | X20: =IFERROR(INDEX(Ratings!$E$5:$E$500,MATCH(A20,Ratings!$A$5:$A$500,0)),"") | Y20: =IFERROR(INDEX(Ratings!$G$5:$G$500,MATCH(A20,Ratings!$A$5:$A$500,0)),"") | Z20: =IFERROR(INDEX(Ratings!$I$5:$I$500,MATCH(A20,Ratings!$A$5:$A$500,0)),"")
A21: F0017 | B21: Alien³ | C21: 1992 | D21: Blu-ray | E21: Alien | I21: After escaping with Newt and Hicks from the alien planet, Ripley crash lands on Fiorina 161, a prison planet and host to a correctional facility. Unfortunately, although Newt and Hicks do not survive the crash, a more unwelcome visitor does. The prison does not allow weapons of any kind, and with aid being a long time away, the prisoners must simply survive in any way they can. | J21: David Fincher | K21: 114 | L21: Science Fiction, Horror, Action | M21: 20th Century Fox, Brandywine Productions | N21: https://huggingface.co/datasets/HenryWaltson/TMDB-IMDB-Movies-Dataset | O21: https://huggingface.co/datasets/HenryWaltson/TMDB-IMDB-Movies-Dataset | P21: Sigourney Weaver | Q21: Charles S. Dutton | R21: Charles Dance | S21: Paul McGann | T21: Brian Glover | U21: 0 | V21: 0 | X21: =IFERROR(INDEX(Ratings!$E$5:$E$500,MATCH(A21,Ratings!$A$5:$A$500,0)),"") | Y21: =IFERROR(INDEX(Ratings!$G$5:$G$500,MATCH(A21,Ratings!$A$5:$A$500,0)),"") | Z21: =IFERROR(INDEX(Ratings!$I$5:$I$500,MATCH(A21,Ratings!$A$5:$A$500,0)),"")
A22: F0018 | B22: Alien Resurrection | C22: 1997 | D22: Blu-ray | E22: Alien | I22: Two hundred years after Lt. Ripley died, a group of scientists clone her, hoping to breed the ultimate weapon. But the new Ripley is full of surprises … as are the new aliens. Ripley must team with a band of smugglers to keep the creatures from reaching Earth. | J22: Jean-Pierre Jeunet | K22: 109 | L22: Science Fiction, Horror, Action | M22: Brandywine Productions, 20th Century Fox | N22: https://huggingface.co/datasets/HenryWaltson/TMDB-IMDB-Movies-Dataset | O22: https://huggingface.co/datasets/HenryWaltson/TMDB-IMDB-Movies-Dataset | P22: Sigourney Weaver | Q22: Winona Ryder | R22: Dominique Pinon | S22: Ron Perlman | T22: Gary Dourdan | U22: 0 | V22: 0 | X22: =IFERROR(INDEX(Ratings!$E$5:$E$500,MATCH(A22,Ratings!$A$5:$A$500,0)),"") | Y22: =IFERROR(INDEX(Ratings!$G$5:$G$500,MATCH(A22,Ratings!$A$5:$A$500,0)),"") | Z22: =IFERROR(INDEX(Ratings!$I$5:$I$500,MATCH(A22,Ratings!$A$5:$A$500,0)),"")
A23: F0019 | B23: The Amazing Spider-Man | C23: 2012 | D23: Blu-ray | E23: Spider-Man | I23: A teenage Peter Parker grapples with both high school and amazing super-human crises as his alter-ego Spider-Man. | J23: Marc Webb | K23: 136 | L23: Action, Adventure, Fantasy | M23: Marvel Entertainment, Laura Ziskin Productions, Columbia Pictures | N23: https://huggingface.co/datasets/HenryWaltson/TMDB-IMDB-Movies-Dataset | O23: https://huggingface.co/datasets/HenryWaltson/TMDB-IMDB-Movies-Dataset | P23: Andrew Garfield | Q23: Emma Stone | R23: Rhys Ifans | S23: Denis Leary | T23: Martin Sheen | U23: 0 | V23: 0 | X23: =IFERROR(INDEX(Ratings!$E$5:$E$500,MATCH(A23,Ratings!$A$5:$A$500,0)),"") | Y23: =IFERROR(INDEX(Ratings!$G$5:$G$500,MATCH(A23,Ratings!$A$5:$A$500,0)),"") | Z23: =IFERROR(INDEX(Ratings!$I$5:$I$500,MATCH(A23,Ratings!$A$5:$A$500,0)),"")
A24: F0020 | B24: American Hustle | C24: 2013 | D24: Blu-ray | I24: A conman and his seductive partner are forced to work for a wild FBI agent, who pushes them into a world of Jersey power-brokers and the Mafia. | J24: David O. Russell | K24: 138 | L24: Drama, Crime | M24: Annapurna Pictures, Atlas Entertainment, Columbia Pictures | N24: https://huggingface.co/datasets/HenryWaltson/TMDB-IMDB-Movies-Dataset | O24: https://huggingface.co/datasets/HenryWaltson/TMDB-IMDB-Movies-Dataset | P24: Christian Bale | Q24: Bradley Cooper | R24: Amy Adams | S24: Jeremy Renner | T24: Jennifer Lawrence | U24: 10 | V24: 0 | W24: Nominated | X24: =IFERROR(INDEX(Ratings!$E$5:$E$500,MATCH(A24,Ratings!$A$5:$A$500,0)),"") | Y24: =IFERROR(INDEX(Ratings!$G$5:$G$500,MATCH(A24,Ratings!$A$5:$A$500,0)),"") | Z24: =IFERROR(INDEX(Ratings!$I$5:$I$500,MATCH(A24,Ratings!$A$5:$A$500,0)),"")
A25: F0021 | B25: A Million Ways to Die in the West | C25: 2014 | D25: Blu-ray | I25: As a cowardly farmer begins to fall for the mysterious new woman in town, he must put his new-found courage to the test when her husband, a notorious gun-slinger, announces his arrival. | J25: Seth MacFarlane | K25: 116 | L25: Comedy, Western | M25: RGB Media, Fuzzy Door Productions, MRC | N25: https://huggingface.co/datasets/HenryWaltson/TMDB-IMDB-Movies-Dataset | O25: https://huggingface.co/datasets/HenryWaltson/TMDB-IMDB-Movies-Dataset | P25: Seth MacFarlane | Q25: Charlize Theron | R25: Amanda Seyfried | S25: Liam Neeson | T25: Giovanni Ribisi | U25: 0 | V25: 0 | X25: =IFERROR(INDEX(Ratings!$E$5:$E$500,MATCH(A25,Ratings!$A$5:$A$500,0)),"") | Y25: =IFERROR(INDEX(Ratings!$G$5:$G$500,MATCH(A25,Ratings!$A$5:$A$500,0)),"") | Z25: =IFERROR(INDEX(Ratings!$I$5:$I$500,MATCH(A25,Ratings!$A$5:$A$500,0)),"")
A26: F0022 | B26: Anchorman: The Legend of Ron Burgundy | C26: 2004 | D26: Blu-ray | E26: Anchorman | I26: It's the 1970s and San Diego anchorman Ron Burgundy is the top dog in local TV, but that's all about to change when ambitious reporter Veronica Corningstone arrives as a new employee at his station. | J26: Adam McKay | K26: 95 | L26: Comedy | M26: DreamWorks Pictures, Apatow Productions | N26: https://huggingface.co/datasets/HenryWaltson/TMDB-IMDB-Movies-Dataset | O26: https://huggingface.co/datasets/HenryWaltson/TMDB-IMDB-Movies-Dataset | P26: Will Ferrell | Q26: Christina Applegate | R26: Paul Rudd | S26: Steve Carell | T26: David Koechner | U26: 0 | V26: 0 | X26: =IFERROR(INDEX(Ratings!$E$5:$E$500,MATCH(A26,Ratings!$A$5:$A$500,0)),"") | Y26: =IFERROR(INDEX(Ratings!$G$5:$G$500,MATCH(A26,Ratings!$A$5:$A$500,0)),"") | Z26: =IFERROR(INDEX(Ratings!$I$5:$I$500,MATCH(A26,Ratings!$A$5:$A$500,0)),"")
A27: F0023 | B27: Angels & Demons | C27: 2009 | D27: Blu-ray | I27: Harvard symbologist Robert Langdon is recruited by the Vatican to investigate the apparent return of the Illuminati – a secret, underground organization – after four cardinals are kidnapped on the night of the papal conclave. | J27: Ron Howard | K27: 138 | L27: Thriller, Mystery | M27: Columbia Pictures, Imagine Entertainment, Skylark Productions | N27: https://huggingface.co/datasets/HenryWaltson/TMDB-IMDB-Movies-Dataset | O27: https://huggingface.co/datasets/HenryWaltson/TMDB-IMDB-Movies-Dataset | P27: Tom Hanks | Q27: Ewan McGregor | R27: Ayelet Zurer | S27: Stellan Skarsgård | T27: Pierfrancesco Favino | U27: 0 | V27: 0 | X27: =IFERROR(INDEX(Ratings!$E$5:$E$500,MATCH(A27,Ratings!$A$5:$A$500,0)),"") | Y27: =IFERROR(INDEX(Ratings!$G$5:$G$500,MATCH(A27,Ratings!$A$5:$A$500,0)),"") | Z27: =IFERROR(INDEX(Ratings!$I$5:$I$500,MATCH(A27,Ratings!$A$5:$A$500,0)),"")
A28: F0024 | B28: Anuvahood | C28: 2011 | D28: Blu-ray | I28: Kenneth (who likes to call himself Kay) begins to realise he's just another wannabe bad boy... even less than a loser in fact. After quitting his job at Laimsbury's, Kay vows to become a respected gangster... or cry trying. A pulls-no-punches, coming-of-age story, centering on one directionless hopeless "shotter", who finds his true worth in the face of urban adversity. | J28: Adam Deacon, Daniel Toland | K28: 88 | L28: Comedy | M28: Gunslinger, Gateway Films, Cabin Fever Films | N28: https://huggingface.co/datasets/HenryWaltson/TMDB-IMDB-Movies-Dataset | O28: https://huggingface.co/datasets/HenryWaltson/TMDB-IMDB-Movies-Dataset | P28: Adam Deacon | Q28: Ollie Barbieri | R28: Jazzie Zonzolo | S28: Richie Campbell | T28: Jaime Winstone | U28: 0 | V28: 0 | X28: =IFERROR(INDEX(Ratings!$E$5:$E$500,MATCH(A28,Ratings!$A$5:$A$500,0)),"") | Y28: =IFERROR(INDEX(Ratings!$G$5:$G$500,MATCH(A28,Ratings!$A$5:$A$500,0)),"") | Z28: =IFERROR(INDEX(Ratings!$I$5:$I$500,MATCH(A28,Ratings!$A$5:$A$500,0)),"")
A29: F0025 | B29: Argo | C29: 2012 | D29: Blu-ray | I29: As the Iranian revolution reaches a boiling point, a CIA 'exfiltration' specialist concocts a risky plan to free six Americans who have found shelter at the home of the Canadian ambassador. | J29: Ben Affleck | K29: 120 | L29: Drama, Thriller | M29: GK Films, Warner Bros. Pictures, Smoke House Pictures | N29: https://huggingface.co/datasets/HenryWaltson/TMDB-IMDB-Movies-Dataset | O29: https://huggingface.co/datasets/HenryWaltson/TMDB-IMDB-Movies-Dataset | P29: Ben Affleck | Q29: Bryan Cranston | R29: Alan Arkin | S29: John Goodman | T29: Victor Garber | U29: 7 | V29: 3 | W29: Winner | X29: =IFERROR(INDEX(Ratings!$E$5:$E$500,MATCH(A29,Ratings!$A$5:$A$500,0)),"") | Y29: =IFERROR(INDEX(Ratings!$G$5:$G$500,MATCH(A29,Ratings!$A$5:$A$500,0)),"") | Z29: =IFERROR(INDEX(Ratings!$I$5:$I$500,MATCH(A29,Ratings!$A$5:$A$500,0)),"")
A30: F0026 | B30: The A-Team | C30: 2010 | D30: Blu-ray | I30: A man who loves when a plan comes together, Col. Hannibal Smith leads a close-knit team of elite operatives and Iraq War veterans. Framed for a crime they didn't commit, Smith and his men, Capt. H.M. ‘Howling Mad’ Murdock , Sgt. Bosco ‘B.A.’ Baracus, and Lt. Templeton ‘Faceman’ Peck, break out and go rogue, using their special talents to clear their names and find the perpetrator. Hot on their trail is Capt. Charissa Sosa, who was once involved with a member of Smith's team and has sworn to capture them, no matter what it takes. | J30: Joe Carnahan | K30: 117 | L30: Thriller, Action, Adventure, Comedy, Crime | M30: Phoenix Film Partners, Dune Entertainment, Stephen J. Cannell Productions | N30: https://huggingface.co/datasets/HenryWaltson/TMDB-IMDB-Movies-Dataset | O30: https://huggingface.co/datasets/HenryWaltson/TMDB-IMDB-Movies-Dataset | P30: Liam Neeson | Q30: Bradley Cooper | R30: Jessica Biel | S30: Quinton 'Rampage' Jackson | T30: Sharlto Copley | U30: 0 | V30: 0 | X30: =IFERROR(INDEX(Ratings!$E$5:$E$500,MATCH(A30,Ratings!$A$5:$A$500,0)),"") | Y30: =IFERROR(INDEX(Ratings!$G$5:$G$500,MATCH(A30,Ratings!$A$5:$A$500,0)),"") | Z30: =IFERROR(INDEX(Ratings!$I$5:$I$500,MATCH(A30,Ratings!$A$5:$A$500,0)),"")
A31: F0027 | B31: Attack the Block | C31: 2011 | D31: Blu-ray | I31: A South London teen gang must team up with the other residents of their housing estate to protect the neighbourhood from a terrifying alien invasion. | J31: Joe Cornish | K31: 88 | L31: Action, Comedy, Science Fiction | M31: UK Film Council, Film4 Productions, StudioCanal | N31: https://huggingface.co/datasets/HenryWaltson/TMDB-IMDB-Movies-Dataset | O31: https://huggingface.co/datasets/HenryWaltson/TMDB-IMDB-Movies-Dataset | P31: John Boyega | Q31: Jodie Whittaker | R31: Nick Frost | S31: Alex Esmail | T31: Luke Treadaway | U31: 0 | V31: 0 | X31: =IFERROR(INDEX(Ratings!$E$5:$E$500,MATCH(A31,Ratings!$A$5:$A$500,0)),"") | Y31: =IFERROR(INDEX(Ratings!$G$5:$G$500,MATCH(A31,Ratings!$A$5:$A$500,0)),"") | Z31: =IFERROR(INDEX(Ratings!$I$5:$I$500,MATCH(A31,Ratings!$A$5:$A$500,0)),"")
A32: F0028 | B32: Avatar | C32: 2009 | D32: Blu-ray | E32: Avatar | I32: In the 22nd century, a paraplegic Marine is dispatched to the moon Pandora on a unique mission, but becomes torn between following orders and protecting an alien civilization. | J32: James Cameron | K32: 162 | L32: Action, Adventure, Fantasy, Science Fiction | M32: Dune Entertainment, Lightstorm Entertainment, 20th Century Fox | N32: https://huggingface.co/datasets/HenryWaltson/TMDB-IMDB-Movies-Dataset | O32: https://huggingface.co/datasets/HenryWaltson/TMDB-IMDB-Movies-Dataset | P32: Sam Worthington | Q32: Zoe Saldaña | R32: Sigourney Weaver | S32: Stephen Lang | T32: Michelle Rodriguez | U32: 9 | V32: 3 | W32: Nominated | X32: =IFERROR(INDEX(Ratings!$E$5:$E$500,MATCH(A32,Ratings!$A$5:$A$500,0)),"") | Y32: =IFERROR(INDEX(Ratings!$G$5:$G$500,MATCH(A32,Ratings!$A$5:$A$500,0)),"") | Z32: =IFERROR(INDEX(Ratings!$I$5:$I$500,MATCH(A32,Ratings!$A$5:$A$500,0)),"")
A33: F0029 | B33: The Avengers | C33: 2012 | D33: Blu-ray | E33: MCU | I33: When an unexpected enemy emerges and threatens global safety and security, Nick Fury, director of the international peacekeeping agency known as S.H.I.E.L.D., finds himself in need of a team to pull the world back from the brink of disaster. Spanning the globe, a daring recruitment effort begins! | J33: Joss Whedon | K33: 143 | L33: Science Fiction, Action, Adventure | M33: Marvel Studios | N33: https://huggingface.co/datasets/HenryWaltson/TMDB-IMDB-Movies-Dataset | O33: https://huggingface.co/datasets/HenryWaltson/TMDB-IMDB-Movies-Dataset | P33: Robert Downey Jr. | Q33: Chris Evans | R33: Mark Ruffalo | S33: Chris Hemsworth | T33: Scarlett Johansson | U33: 1 | V33: 0 | X33: =IFERROR(INDEX(Ratings!$E$5:$E$500,MATCH(A33,Ratings!$A$5:$A$500,0)),"") | Y33: =IFERROR(INDEX(Ratings!$G$5:$G$500,MATCH(A33,Ratings!$A$5:$A$500,0)),"") | Z33: =IFERROR(INDEX(Ratings!$I$5:$I$500,MATCH(A33,Ratings!$A$5:$A$500,0)),"")
A34: F0030 | B34: Avengers: Infinity War | C34: 2018 | D34: 4K UHD | E34: MCU | I34: As the Avengers and their allies have continued to protect the world from threats too large for any one hero to handle, a new danger has emerged from the cosmic shadows: Thanos. A despot of intergalactic infamy, his goal is to collect all six Infinity Stones, artifacts of unimaginable power, and use them to inflict his twisted will on all of reality. Everything the Avengers have fought for has led up to this moment - the fate of Earth and existence itself has never been more uncertain. | J34: Anthony Russo, Joe Russo | K34: 149 | L34: Adventure, Action, Science Fiction | M34: Marvel Studios | N34: https://huggingface.co/datasets/HenryWaltson/TMDB-IMDB-Movies-Dataset | O34: https://huggingface.co/datasets/HenryWaltson/TMDB-IMDB-Movies-Dataset | P34: Robert Downey Jr. | Q34: Chris Evans | R34: Chris Hemsworth | S34: Josh Brolin | T34: Mark Ruffalo | U34: 1 | V34: 0 | X34: =IFERROR(INDEX(Ratings!$E$5:$E$500,MATCH(A34,Ratings!$A$5:$A$500,0)),"") | Y34: =IFERROR(INDEX(Ratings!$G$5:$G$500,MATCH(A34,Ratings!$A$5:$A$500,0)),"") | Z34: =IFERROR(INDEX(Ratings!$I$5:$I$500,MATCH(A34,Ratings!$A$5:$A$500,0)),"")
A35: F0031 | B35: Avengers: Endgame | C35: 2019 | D35: 4K UHD | E35: MCU | I35: After the devastating events of Avengers: Infinity War, the universe is in ruins due to the efforts of the Mad Titan, Thanos. With the help of remaining allies, the Avengers must assemble once more in order to undo Thanos' actions and restore order to the universe once and for all, no matter what consequences may be in store. | J35: Anthony Russo, Joe Russo | K35: 181 | L35: Adventure, Science Fiction, Action | M35: Marvel Studios | N35: https://huggingface.co/datasets/HenryWaltson/TMDB-IMDB-Movies-Dataset | O35: https://huggingface.co/datasets/HenryWaltson/TMDB-IMDB-Movies-Dataset | P35: Robert Downey Jr. | Q35: Chris Evans | R35: Mark Ruffalo | S35: Chris Hemsworth | T35: Scarlett Johansson | U35: 1 | V35: 0 | X35: =IFERROR(INDEX(Ratings!$E$5:$E$500,MATCH(A35,Ratings!$A$5:$A$500,0)),"") | Y35: =IFERROR(INDEX(Ratings!$G$5:$G$500,MATCH(A35,Ratings!$A$5:$A$500,0)),"") | Z35: =IFERROR(INDEX(Ratings!$I$5:$I$500,MATCH(A35,Ratings!$A$5:$A$500,0)),"")
A36: F0032 | B36: Baby Driver | C36: 2017 | D36: Blu-ray | I36: After being coerced into working for a crime boss, a young getaway driver finds himself taking part in a heist doomed to fail. | J36: Edgar Wright | K36: 113 | L36: Action, Crime | M36: Big Talk Productions, Working Title Films | N36: https://huggingface.co/datasets/HenryWaltson/TMDB-IMDB-Movies-Dataset | O36: https://huggingface.co/datasets/HenryWaltson/TMDB-IMDB-Movies-Dataset | P36: Ansel Elgort | Q36: Kevin Spacey | R36: Lily James | S36: Jon Hamm | T36: Jamie Foxx | U36: 3 | V36: 0 | X36: =IFERROR(INDEX(Ratings!$E$5:$E$500,MATCH(A36,Ratings!$A$5:$A$500,0)),"") | Y36: =IFERROR(INDEX(Ratings!$G$5:$G$500,MATCH(A36,Ratings!$A$5:$A$500,0)),"") | Z36: =IFERROR(INDEX(Ratings!$I$5:$I$500,MATCH(A36,Ratings!$A$5:$A$500,0)),"")
A37: F0033 | B37: Back to the Future | C37: 1985 | D37: Blu-ray | E37: Back to the Future | F37: Back to the Future Trilogy (Box Set) | I37: Owned via Back to the Future Trilogy (Box Set). | J37: Robert Zemeckis | K37: 116 | L37: Adventure, Comedy, Science Fiction | M37: Universal Pictures, Amblin Entertainment | N37: https://huggingface.co/datasets/HenryWaltson/TMDB-IMDB-Movies-Dataset | O37: https://huggingface.co/datasets/HenryWaltson/TMDB-IMDB-Movies-Dataset | P37: Michael J. Fox | Q37: Christopher Lloyd | R37: Crispin Glover | S37: Lea Thompson | T37: Claudia Wells | U37: 4 | V37: 1 | X37: =IFERROR(INDEX(Ratings!$E$5:$E$500,MATCH(A37,Ratings!$A$5:$A$500,0)),"") | Y37: =IFERROR(INDEX(Ratings!$G$5:$G$500,MATCH(A37,Ratings!$A$5:$A$500,0)),"") | Z37: =IFERROR(INDEX(Ratings!$I$5:$I$500,MATCH(A37,Ratings!$A$5:$A$500,0)),"")
A38: F0034 | B38: Back to the Future Part II | C38: 1989 | D38: Blu-ray | E38: Back to the Future | F38: Back to the Future Trilogy (Box Set) | I38: Owned via Back to the Future Trilogy (Box Set). | J38: Robert Zemeckis | K38: 108 | L38: Adventure, Comedy, Science Fiction | M38: Universal Pictures, Amblin Entertainment | N38: https://huggingface.co/datasets/HenryWaltson/TMDB-IMDB-Movies-Dataset | O38: https://huggingface.co/datasets/HenryWaltson/TMDB-IMDB-Movies-Dataset | P38: Michael J. Fox | Q38: Christopher Lloyd | R38: Lea Thompson | S38: Thomas F. Wilson | T38: Elisabeth Shue | U38: 1 | V38: 0 | X38: =IFERROR(INDEX(Ratings!$E$5:$E$500,MATCH(A38,Ratings!$A$5:$A$500,0)),"") | Y38: =IFERROR(INDEX(Ratings!$G$5:$G$500,MATCH(A38,Ratings!$A$5:$A$500,0)),"") | Z38: =IFERROR(INDEX(Ratings!$I$5:$I$500,MATCH(A38,Ratings!$A$5:$A$500,0)),"")
A39: F0035 | B39: Back to the Future Part III | C39: 1990 | D39: Blu-ray | E39: Back to the Future | F39: Back to the Future Trilogy (Box Set) | I39: Owned via Back to the Future Trilogy (Box Set). | J39: Robert Zemeckis | K39: 118 | L39: Adventure, Comedy, Science Fiction, Western | M39: Universal Pictures, Amblin Entertainment | N39: https://huggingface.co/datasets/HenryWaltson/TMDB-IMDB-Movies-Dataset | O39: https://huggingface.co/datasets/HenryWaltson/TMDB-IMDB-Movies-Dataset | P39: Michael J. Fox | Q39: Christopher Lloyd | R39: Mary Steenburgen | S39: Thomas F. Wilson | T39: Lea Thompson | U39: 0 | V39: 0 | X39: =IFERROR(INDEX(Ratings!$E$5:$E$500,MATCH(A39,Ratings!$A$5:$A$500,0)),"") | Y39: =IFERROR(INDEX(Ratings!$G$5:$G$500,MATCH(A39,Ratings!$A$5:$A$500,0)),"") | Z39: =IFERROR(INDEX(Ratings!$I$5:$I$500,MATCH(A39,Ratings!$A$5:$A$500,0)),"")
A40: F0036 | B40: Bad Boys | C40: 1995 | D40: Blu-ray | E40: Bad Boys | F40: Bad Boys I & II (Box Set) | I40: Owned via Bad Boys I & II (Box Set). | J40: Michael Bay | K40: 119 | L40: Action, Comedy, Crime, Thriller | M40: Columbia Pictures, Don Simpson/Jerry Bruckheimer Films | N40: https://huggingface.co/datasets/HenryWaltson/TMDB-IMDB-Movies-Dataset | O40: https://huggingface.co/datasets/HenryWaltson/TMDB-IMDB-Movies-Dataset | P40: Will Smith | Q40: Martin Lawrence | R40: Téa Leoni | S40: Tchéky Karyo | T40: Joe Pantoliano | U40: 0 | V40: 0 | X40: =IFERROR(INDEX(Ratings!$E$5:$E$500,MATCH(A40,Ratings!$A$5:$A$500,0)),"") | Y40: =IFERROR(INDEX(Ratings!$G$5:$G$500,MATCH(A40,Ratings!$A$5:$A$500,0)),"") | Z40: =IFERROR(INDEX(Ratings!$I$5:$I$500,MATCH(A40,Ratings!$A$5:$A$500,0)),"")
A41: F0037 | B41: Bad Boys II | C41: 2003 | D41: Blu-ray | E41: Bad Boys | F41: Bad Boys I & II (Box Set) | I41: Owned via Bad Boys I & II (Box Set). | J41: Michael Bay | K41: 147 | L41: Action, Comedy, Crime, Thriller | M41: Columbia Pictures, Don Simpson/Jerry Bruckheimer Films | N41: https://huggingface.co/datasets/HenryWaltson/TMDB-IMDB-Movies-Dataset | O41: https://huggingface.co/datasets/HenryWaltson/TMDB-IMDB-Movies-Dataset | P41: Martin Lawrence | Q41: Will Smith | R41: Jordi Mollà | S41: Gabrielle Union | T41: Peter Stormare | U41: 0 | V41: 0 | X41: =IFERROR(INDEX(Ratings!$E$5:$E$500,MATCH(A41,Ratings!$A$5:$A$500,0)),"") | Y41: =IFERROR(INDEX(Ratings!$G$5:$G$500,MATCH(A41,Ratings!$A$5:$A$500,0)),"") | Z41: =IFERROR(INDEX(Ratings!$I$5:$I$500,MATCH(A41,Ratings!$A$5:$A$500,0)),"")
...

Sheet Wishlist
A1: 🛒 WISHLIST & NEXT BUYS
A2: Your original wanted films plus recommendations based on the collection. Prices can be filled in as we hunt for bargains.
A4: Title | B4: Type | C4: Priority (1-5) | D4: Target Price (£) | E4: Cheapest Found (£) | F4: Where | G4: Date Checked | H4: Already Owned? | I4: Notes
A5: One Battle After Another | B5: Your list | C5: 4 | H5: =IF(A5="","",IF(COUNTIF(Collection!$B$5:$B$500,A5)>0,"Yes","No")) | I5: From your original wishlist
A6: Everything Everywhere All at Once | B6: Your list | C6: 3 | H6: =IF(A6="","",IF(COUNTIF(Collection!$B$5:$B$500,A6)>0,"Yes","No")) | I6: From your original wishlist
A7: CODA | B7: Your list | C7: 2 | H7: =IF(A7="","",IF(COUNTIF(Collection!$B$5:$B$500,A7)>0,"Yes","No")) | I7: From your original wishlist
A8: Parasite | B8: Your list | C8: 3 | H8: =IF(A8="","",IF(COUNTIF(Collection!$B$5:$B$500,A8)>0,"Yes","No")) | I8: From your original wishlist
A9: Green Book | B9: Your list | C9: 4 | H9: =IF(A9="","",IF(COUNTIF(Collection!$B$5:$B$500,A9)>0,"Yes","No")) | I9: From your original wishlist
A10: The Shape of Water | B10: Your list | C10: 3 | H10: =IF(A10="","",IF(COUNTIF(Collection!$B$5:$B$500,A10)>0,"Yes","No")) | I10: From your original wishlist
A11: Moonlight | B11: Your list | C11: 5 | H11: =IF(A11="","",IF(COUNTIF(Collection!$B$5:$B$500,A11)>0,"Yes","No")) | I11: From your original wishlist
A12: Spotlight | B12: Your list | C12: 3 | H12: =IF(A12="","",IF(COUNTIF(Collection!$B$5:$B$500,A12)>0,"Yes","No")) | I12: From your original wishlist
A13: Birdman or (The Unexpected Virtue of Ignorance) | B13: Your list | C13: 4 | H13: =IF(A13="","",IF(COUNTIF(Collection!$B$5:$B$500,A13)>0,"Yes","No")) | I13: From your original wishlist
A14: 12 Years a Slave | B14: Your list | C14: 2 | H14: =IF(A14="","",IF(COUNTIF(Collection!$B$5:$B$500,A14)>0,"Yes","No")) | I14: From your original wishlist
A15: The Artist | B15: Your list | C15: 5 | H15: =IF(A15="","",IF(COUNTIF(Collection!$B$5:$B$500,A15)>0,"Yes","No")) | I15: From your original wishlist
A16: The Hurt Locker | B16: Your list | C16: 2 | H16: =IF(A16="","",IF(COUNTIF(Collection!$B$5:$B$500,A16)>0,"Yes","No")) | I16: From your original wishlist
... A44: 1917 | B44: Recommended | C44: 4 | H44: =IF(A44="","",IF(COUNTIF(Collection!$B$5:$B$500,A44)>0,"Yes","No")) | I44: Technically impressive war film that fits alongside Dunkirk, Hacksaw Ridge and Saving Private Ryan.
A45: The Wolf of Wall Street | B45: Recommended | C45: 3 | H45: =IF(A46="","",IF(COUNTIF(Collection!$B$5:$B$500,A46)>0,"Yes","No")) | I45: If your existing copy turns out not to be in the catalogue, this is worth confirming rather than rebuying.
H46: =IF(A47="","",IF(COUNTIF(Collection!$B$5:$B$500,A47)>0,"Yes","No"))
H47: =IF(A48="","",IF(COUNTIF(Collection!$B$5:$B$500,A48)>0,"Yes","No"))
H48: =IF(A49="","",IF(COUNTIF(Collection!$B$5:$B$500,A49)>0,"Yes","No"))
H49: =IF(A50="","",IF(COUNTIF(Collection!$B$5:$B$500,A50)>0,"Yes","No"))
H50: =IF(A51="","",IF(COUNTIF(Collection!$B$5:$B$500,A51)>0,"Yes","No"))
H51: =IF(A52="","",IF(COUNTIF(Collection!$B$5:$B$500,A52)>0,"Yes","No"))
H52: =IF(A53="","",IF(COUNTIF(Collection!$B$5:$B$500,A53)>0,"Yes","No"))
H53: =IF(A54="","",IF(COUNTIF(Collection!$B$5:$B$500,A54)>0,"Yes","No"))
H54: =IF(A55="","",IF(COUNTIF(Collection!$B$5:$B$500,A55)>0,"Yes","No"))
H55: =IF(A56="","",IF(COUNTIF(Collection!$B$5:$B$500,A56)>0,"Yes","No"))
H56: =IF(A57="","",IF(COUNTIF(Collection!$B$5:$B$500,A57)>0,"Yes","No"))
H57: =IF(A58="","",IF(COUNTIF(Collection!$B$5:$B$500,A58)>0,"Yes","No"))
... H96: =IF(A97="","",IF(COUNTIF(Collection!$B$5:$B$500,A97)>0,"Yes","No"))
A100: Pulp Fiction | C100: 2 | D100: 8 | H100: No
A101: Jumanji | C101: 3 | H101: No
A102: Pirates of the Caribbean: Dead Men Tell No Tales | C102: 3 | H102: No
A103: Pirates of the Caribbean: Dead Man's Chest | C103: 3 | H103: No
A104: Napoleon Dynamite | C104: 3 | H104: No

Sheet Franchise Tracker
A1: 🏆 COLLECTION / FRANCHISE TRACKER
A2: Owned counts are calculated from the Collection tab. Target totals are editable so you can define exactly what 'complete' means to you.
A4: Collection | B4: Owned Films | C4: Target Films | D4: Missing | E4: % Complete
A5: James Bond | B5: =COUNTIF(Collection!$E$5:$E$500,A5) | C5: 5 | D5: =IF(C5="","",MAX(C5-B5,0)) | E5: =IF(C5="","",MIN(B5/C5,1))
A6: Alien | B6: =COUNTIF(Collection!$E$5:$E$500,A6) | C6: 7 | D6: =IF(C6="","",MAX(C6-B6,0)) | E6: =IF(C6="","",MIN(B6/C6,1))
A7: Bourne | B7: =COUNTIF(Collection!$E$5:$E$500,A7) | C7: 5 | D7: =IF(C7="","",MAX(C7-B7,0)) | E7: =IF(C7="","",MIN(B7/C7,1))
A8: Fast & Furious | B8: =COUNTIF(Collection!$E$5:$E$500,A8) | C8: 11 | D8: =IF(C8="","",MAX(C8-B8,0)) | E8: =IF(C8="","",MIN(B8/C8,1))
A9: Harry Potter | B9: =COUNTIF(Collection!$E$5:$E$500,A9) | C9: 8 | D9: =IF(C9="","",MAX(C9-B9,0)) | E9: =IF(C9="","",MIN(B9/C9,1))
A10: Wizarding World | B10: =COUNTIF(Collection!$E$5:$E$500,A10) | C10: 3 | D10: =IF(C10="","",MAX(C10-B10,0)) | E10: =IF(C10="","",MIN(B10/C10,1))
A11: Hobbit | B11: =COUNTIF(Collection!$E$5:$E$500,A11) | C11: 3 | D11: =IF(C11="","",MAX(C11-B11,0)) | E11: =IF(C11="","",MIN(B11/C11,1))
A12: Lord of the Rings | B12: =COUNTIF(Collection!$E$5:$E$500,A12) | C12: 3 | D12: =IF(C12="","",MAX(C12-B12,0)) | E12: =IF(C12="","",MIN(B12/C12,1))
A13: Mission: Impossible | B13: =COUNTIF(Collection!$E$5:$E$500,A13) | C13: 8 | D13: =IF(C13="","",MAX(C13-B13,0)) | E13: =IF(C13="","",MIN(B13/C13,1))
A14: X-Men | B14: =COUNTIF(Collection!$E$5:$E$500,A14) | C14: 10 | D14: =IF(C14="","",MAX(C14-B14,0)) | E14: =IF(C14="","",MIN(B14/C14,1))
A15: Deadpool / X-Men | B15: =COUNTIF(Collection!$E$5:$E$500,A15) | C15: 3 | D15: =IF(C15="","",MAX(C15-B15,0)) | E15: =IF(C15="","",MIN(B15/C15,1))
A16: Transformers | B16: =COUNTIF(Collection!$E$5:$E$500,A16) | C16: 8 | D16: =IF(C16="","",MAX(C16-B16,0)) | E16: =IF(C16="","",MIN(B16/C16,1))
... A29: Rio | B29: =COUNTIF(Collection!$E$5:$E$500,A29) | C29: 2 | D29: =IF(C29="","",MAX(C29-B29,0)) | E29: =IF(C29="","",MIN(B29/C29,1))
A30: Pitch Perfect
A31: Jurassic Park / World | B31: =COUNTIF(Collection!$E$5:$E$500,A31) | C31: 7 | D31: =IF(C31="","",MAX(C31-B31,0)) | E31: =IF(C31="","",MIN(B31/C31,1))
A32: Kick-Ass | B32: =COUNTIF(Collection!$E$5:$E$500,A32) | C32: 2 | D32: =IF(C32="","",MAX(C32-B32,0)) | E32: =IF(C32="","",MIN(B32/C32,1))
A33: LEGO Movie | B33: =COUNTIF(Collection!$E$5:$E$500,A33) | C33: 4 | D33: =IF(C33="","",MAX(C33-B33,0)) | E33: =IF(C33="","",MIN(B33/C33,1))
A34: How to Train Your Dragon | B34: =COUNTIF(Collection!$E$5:$E$500,A34) | C34: 3 | D34: =IF(C34="","",MAX(C34-B34,0)) | E34: =IF(C34="","",MIN(B34/C34,1))
A35: Grown Ups | B35: =COUNTIF(Collection!$E$5:$E$500,A35) | C35: 2 | D35: =IF(C35="","",MAX(C35-B35,0)) | E35: =IF(C35="","",MIN(B35/C35,1))
A36: Sherlock Holmes | B36: =COUNTIF(Collection!$E$5:$E$500,A36) | C36: 2 | D36: =IF(C36="","",MAX(C36-B36,0)) | E36: =IF(C36="","",MIN(B36/C36,1))
A37: Taken | B37: =COUNTIF(Collection!$E$5:$E$500,A37) | C37: 3 | D37: =IF(C37="","",MAX(C37-B37,0)) | E37: =IF(C37="","",MIN(B37/C37,1))
A38: Wreck-It Ralph | B38: =COUNTIF(Collection!$E$5:$E$500,A38) | C38: 2 | D38: =IF(C38="","",MAX(C38-B38,0)) | E38: =IF(C38="","",MIN(B38/C38,1))
A39: Monsters, Inc. | B39: =COUNTIF(Collection!$E$5:$E$500,A39) | C39: 2 | D39: =IF(C39="","",MAX(C39-B39,0)) | E39: =IF(C39="","",MIN(B39/C39,1))
A40: MonsterVerse | B40: =COUNTIF(Collection!$E$5:$E$500,A40) | C40: 5 | D40: =IF(C40="","",MAX(C40-B40,0)) | E40: =IF(C40="","",MIN(B40/C40,1))
A41: The Inbetweeners | B41: =COUNTIF(Collection!$E$5:$E$500,A41) | C41: 2 | D41: =IF(C41="","",MAX(C41-B41,0)) | E41: =IF(C41="","",MIN(B41/C41,1))
A42: Anchorman | B42: =COUNTIF(Collection!$E$5:$E$500,A42) | C42: 2 | D42: =IF(C42="","",MAX(C42-B42,0)) | E42: =IF(C42="","",MIN(B42/C42,1))
... A45: Back to the Future | B45: =COUNTIF(Collection!$E$5:$E$500,A45) | C45: 3 | D45: =IF(C45="","",MAX(C45-B45,0)) | E45: =IF(C45="","",MIN(B45/C45,1))
A46: MCU | B46: =COUNTIF(Collection!$E$5:$E$500,A46) | D46: =IF(C46="","",MAX(C46-B46,0)) | E46: =IF(C46="","",MIN(B46/C46,1))
A47: The Dark Knight Trilogy | B47: =COUNTIF(Collection!$E$5:$E$500,A47) | C47: 3 | D47: =IF(C47="","",MAX(C47-B47,0)) | E47: =IF(C47="","",MIN(B47/C47,1))

Sheet Actors
A1: 🎭 ACTORS
A2: Search or filter this sheet by actor name to see every film in your collection where they appear in the top five billed cast.
A4: Actor | B4: Films Owned | C4: Earliest Film | D4: Latest Film | E4: Films in Collection | F4: Film IDs
A5: Hugh Jackman | B5: 12 | C5: 2000 | D5: 2024 | E5: Deadpool & Wolverine, The Greatest Showman, Les Misérables, Logan, The Prestige, Prisoners, X-Men: Days of Future Past, X-Men Origins: Wolverine, X-Men, X2: X-Men United, X-Men: The Last Stand, The Wolverine | F5: F0078, F0127, F0199, F0201, F0257, F0258, F0341, F0343, F0344, F0345, F0346, F0347
A6: Tom Cruise | B6: 12 | C6: 1996 | D6: 2025 | E6: Jack Reacher, Mission: Impossible, Mission: Impossible II, Mission: Impossible III, Mission: Impossible - Ghost Protocol, Mission: Impossible - Rogue Nation, Mission: Impossible - Fallout, Mission: Impossible - Dead Reckoning Part One, Mission: Impossible - The Final Reckoning, Oblivion, War of the Worlds, Tropic Thunder | F6: F0171, F0221, F0222, F0223, F0224, F0225, F0226, F0227, F0228, F0239, F0332, F0324
A7: Ian McKellen | B7: 10 | C7: 2000 | D7: 2014 | E7: The Hobbit: An Unexpected Journey, The Hobbit: The Desolation of Smaug, The Hobbit: The Battle of the Five Armies, The Lord of the Rings: The Fellowship of the Ring, The Lord of the Rings: The Two Towers, The Lord of the Rings: The Return of the King, X-Men: Days of Future Past, X-Men, X2: X-Men United, X-Men: The Last Stand | F7: F0150, F0151, F0152, F0203, F0204, F0205, F0341, F0344, F0345, F0346
A8: Matt Damon | B8: 14 | C8: 1997 | D8: 2023 | E8: The Bourne Identity, The Bourne Supremacy, The Bourne Ultimatum, The Departed, Elysium, Good Will Hunting, Green Zone, The Martian, Oppenheimer, True Grit, Dogma, Deadpool 2, Happy Feet Two, Interstellar | F8: F0053, F0054, F0055, F0081, F0093, F0124, F0129, F0213, F0242, F0325, F0351, F0077, F0145, F0168
A9: Robert Downey Jr. | B9: 11 | C9: 2007 | D9: 2023 | E9: The Avengers, Avengers: Infinity War, Avengers: Endgame, Due Date, Iron Man 3, Oppenheimer, Sherlock Holmes, Sherlock Holmes: A Game of Shadows, Tropic Thunder, Zodiac, Chef | F9: F0029, F0030, F0031, F0091, F0169, F0242, F0278, F0279, F0324, F0350, F0065
A10: Simon Pegg | B10: 13 | C10: 2004 | D10: 2025 | E10: Shaun of the Dead, Hot Fuzz, The World's End, Ice Age: Dawn of the Dinosaurs, Mission: Impossible - Ghost Protocol, Mission: Impossible - Rogue Nation, Mission: Impossible - Fallout, Mission: Impossible - Dead Reckoning Part One, Mission: Impossible - The Final Reckoning, Paul, Mission: Impossible III, Star Trek, Star Wars: The Force Awakens | F10: F0070, F0071, F0072, F0161, F0224, F0225, F0226, F0227, F0228, F0245, F0223, F0291, F0298
A11: Emma Watson | B11: 9 | C11: 2001 | D11: 2014 | E11: Harry Potter and the Philosopher's Stone, Harry Potter and the Chamber of Secrets, Harry Potter and the Prisoner of Azkaban, Harry Potter and the Goblet of Fire, Harry Potter and the Order of the Phoenix, Harry Potter and the Half-Blood Prince, Harry Potter and the Deathly Hallows: Part 1, Harry Potter and the Deathly Hallows: Part 2, Noah | F11: F0137, F0138, F0139, F0140, F0141, F0142, F0143, F0144, F0238
A12: Jason Statham | B12: 10 | C12: 2008 | D12: 2023 | E12: The Bank Job, The Expendables, The Expendables 2, The Expendables 3, Furious 7, The Fate of the Furious, Fast & Furious Presents: Hobbs & Shaw, Hummingbird, Spy, Fast X | F12: F0040, F0095, F0096, F0097, F0107, F0108, F0111, F0156, F0290, F0110
A13: Vin Diesel | B13: 10 | C13: 2001 | D13: 2023 | E13: The Fast and the Furious, Fast & Furious, Fast Five, Fast & Furious 6, Furious 7, The Fate of the Furious, F9: The Fast Saga, Fast X, Riddick, Avengers: Infinity War | F13: F0101, F0104, F0105, F0106, F0107, F0108, F0109, F0110, F0264, F0030
A14: Brad Pitt | B14: 10 | C14: 1995 | D14: 2025 | E14: F1, Fight Club, Fury, Inglourious Basterds, Killing Them Softly, Mr. & Mrs. Smith, Once Upon a Time… in Hollywood, Se7en, Deadpool 2, Happy Feet Two | F14: F0098, F0112, F0117, F0166, F0187, F0231, F0241, F0276, F0077, F0145
A15: Chris Pratt | B15: 10 | C15: 2012 | D15: 2023 | E15: Delivery Man, Jurassic World, Jurassic World: Fallen Kingdom, Jurassic World Dominion, The Lego Movie, The Lego Movie 2: The Second Part, The Magnificent Seven, The Super Mario Bros. Movie, Avengers: Infinity War, Zero Dark Thirty | F15: F0080, F0179, F0180, F0181, F0195, F0196, F0207, F0212, F0030, F0349
A16: Daniel Radcliffe | B16: 8 | C16: 2001 | D16: 2011 | E16: Harry Potter and the Philosopher's Stone, Harry Potter and the Chamber of Secrets, Harry Potter and the Prisoner of Azkaban, Harry Potter and the Goblet of Fire, Harry Potter and the Order of the Phoenix, Harry Potter and the Half-Blood Prince, Harry Potter and the Deathly Hallows: Part 1, Harry Potter and the Deathly Hallows: Part 2 | F16: F0137, F0138, F0139, F0140, F0141, F0142, F0143, F0144
... A481: Dan Fogler | B481: 1 | C481: 2016 | D481: 2016 | E481: Fantastic Beasts and Where to Find Them | F481: F0100
A482: Dan O'Herlihy | B482: 1 | E482: RoboCop | F482: F0268
A483: Daniel Brühl | B483: 3 | C483: 2007 | D483: 2013 | E483: Rush, The Bourne Ultimatum, Inglourious Basterds | F483: F0270, F0055, F0166
A484: Daniel Henney | B484: 2 | C484: 2009 | D484: 2014 | E484: Big Hero 6, X-Men Origins: Wolverine | F484: F0048, F0343
A485: Daniel Mays | B485: 1 | C485: 2008 | D485: 2008 | E485: The Bank Job | F485: F0040
A486: Daniel Olbrychski | B486: 1 | C486: 2010 | D486: 2010 | E486: Salt | F486: F0273
A487: Daniella Pineda | B487: 2 | C487: 2018 | D487: 2022 | E487: Jurassic World: Fallen Kingdom, Jurassic World Dominion | F487: F0180, F0181
A488: Danny Huston | B488: 2 | C488: 2009 | D488: 2010 | E488: X-Men Origins: Wolverine, Robin Hood | F488: F0343, F0267
A489: Dave Bautista | B489: 4 | C489: 2013 | D489: 2019 | E489: Riddick, Spectre, Avengers: Infinity War, Avengers: Endgame | F489: F0264, F0004, F0030, F0031
A490: Dave Foley | B490: 2 | C490: 1998 | D490: 2013 | E490: A Bug's Life, Monsters University | F490: F0012, F0230
A491: Dave Franco | B491: 3 | C491: 2007 | D491: 2014 | E491: 21 Jump Street, The Lego Movie, Superbad | F491: F0007, F0195, F0303
A492: David Corenswet | B492: 1 | C492: 2025 | D492: 2025 | E492: Superman | F492: F0304
A493: David Harris | B493: 1 | C493: 1979 | D493: 1979 | E493: The Warriors | F493: F0334
A494: David Huddleston | B494: 1 | C494: 1998 | D494: 1998 | E494: The Big Lebowski | F494: F0049
... A781: Mélanie Laurent | B781: 1 | C781: 2009 | D781: 2009 | E781: Inglourious Basterds | F781: F0166
A782: Nancy Allen | B782: 1 | E782: RoboCop | F782: F0268
A783: Naomi Watts | B783: 1 | C783: 2005 | D783: 2005 | E783: King Kong | F783: F0188
A784: Nathalie Baye | B784: 1 | C784: 2002 | D784: 2002 | E784: Catch Me If You Can | F784: F0064
A785: Nathalie Boltt | B785: 1 | C785: 2009 | D785: 2009 | E785: District 9 | F785: F0088
A786: Nathalie Kelley | B786: 1 | C786: 2006 | D786: 2006 | E786: The Fast and the Furious: Tokyo Drift | F786: F0103
A787: Nathan Lane | B787: 1 | C787: 1994 | D787: 1994 | E787: The Lion King | F787: F0200
A788: Neil Brown Jr. | B788: 2 | C788: 2011 | D788: 2015 | E788: Straight Outta Compton, Battle: Los Angeles | F788: F0301, F0046
A789: Neil Patrick Harris | B789: 3 | C789: 2013 | D789: 2014 | E789: The Smurfs 2, A Million Ways to Die in the West, Cloudy with a Chance of Meatballs 2 | F789: F0282, F0021, F0067
A790: Nev Scharrel | B790: 1 | C790: 2017 | D790: 2017 | E790: Despicable Me 3 | F790: F0084
A791: Nick Nolte | B791: 3 | C791: 2008 | D791: 2014 | E791: Warrior, Noah, Tropic Thunder | F791: F0333, F0238, F0324
...

Sheet Directors
A1: 🎥 DIRECTORS
A2: Search or filter this sheet by director to see every film in your collection credited to them.
A4: Director | B4: Films Owned | C4: Earliest Film | D4: Latest Film | E4: Films in Collection | F4: Film IDs
A5: Michael Bay | B5: 8 | C5: 1995 | D5: 2017 | E5: Bad Boys, Bad Boys II, Pearl Harbor, Transformers, Transformers: Revenge of the Fallen, Transformers: Dark of the Moon, Transformers: Age of Extinction, Transformers: The Last Knight | F5: F0036, F0037, F0246, F0316, F0317, F0318, F0319, F0320
A6: Christopher Nolan | B6: 7 | C6: 2005 | D6: 2023 | E6: Batman Begins, The Dark Knight, The Dark Knight Rises, Inception, Interstellar, Oppenheimer, The Prestige | F6: F0043, F0044, F0045, F0165, F0168, F0242, F0257
A7: Peter Jackson | B7: 7 | C7: 2001 | D7: 2014 | E7: The Hobbit: An Unexpected Journey, The Hobbit: The Desolation of Smaug, The Hobbit: The Battle of the Five Armies, King Kong, The Lord of the Rings: The Fellowship of the Ring, The Lord of the Rings: The Two Towers, The Lord of the Rings: The Return of the King | F7: F0150, F0151, F0152, F0188, F0203, F0204, F0205
A8: Ridley Scott | B8: 6 | C8: 1979 | D8: 2015 | E8: Alien, Black Hawk Down, Body of Lies, The Martian, Prometheus, Robin Hood | F8: F0015, F0050, F0051, F0213, F0259, F0267
A9: Bryan Singer | B9: 5 | C9: 2000 | D9: 2018 | E9: Bohemian Rhapsody, X-Men: Days of Future Past, X-Men: Apocalypse, X-Men, X2: X-Men United | F9: F0052, F0341, F0342, F0344, F0345
A10: Christopher McQuarrie | B10: 5 | C10: 2012 | D10: 2025 | E10: Jack Reacher, Mission: Impossible - Rogue Nation, Mission: Impossible - Fallout, Mission: Impossible - Dead Reckoning Part One, Mission: Impossible - The Final Reckoning | F10: F0171, F0225, F0226, F0227, F0228
A11: David Fincher | B11: 5 | C11: 1992 | D11: 2011 | E11: Alien³, Fight Club, The Girl with the Dragon Tattoo, Se7en, Zodiac | F11: F0017, F0112, F0120, F0276, F0350
A12: David Yates | B12: 5 | C12: 2007 | D12: 2016 | E12: Fantastic Beasts and Where to Find Them, Harry Potter and the Order of the Phoenix, Harry Potter and the Half-Blood Prince, Harry Potter and the Deathly Hallows: Part 1, Harry Potter and the Deathly Hallows: Part 2 | F12: F0100, F0141, F0142, F0143, F0144
A13: J.J. Abrams | B13: 5 | C13: 2006 | D13: 2019 | E13: Mission: Impossible III, Star Trek, Star Wars: The Force Awakens, Star Wars: The Rise of Skywalker, Super 8 | F13: F0223, F0291, F0298, F0300, F0302
